<?xml version="1.0" ?>

<robot name="excavator" xmlns:xacro="http://www.ros.org/wiki/xacro">
    <link name="base_link_00">
        <visual>
            <origin rpy="0 0 0" xyz="0 0 0"/>
            <geometry>
                <box size="2 2 1"/>
            </geometry>
        </visual>
    </link>

    <joint name="base_link_00__link_01" type="revolute">
        <axis xyz="0 1 0"/>
        <limit effort="1000.0" lower="-3.14" upper="3.14" velocity="0.5"/>
        <origin rpy="0 0 0" xyz="0 0 0.5"/>
        <parent link="base_link_00"/>
        <child link="link_01"/>
    </joint>

    <link name="link_01">
        <visual>
            <origin rpy="0 0 0" xyz="0 0 1.5"/>
            <geometry>
                <cylinder radius="0.3" length="3"/>
            </geometry>
        </visual>
    </link>

    <joint name="link_01_link_02" type="revolute">
        <axis xyz="0 1 0"/>
        <limit effort="1000.0" lower="-3.14" upper="3.14" velocity="0.5"/>
        <origin rpy="0 0 0" xyz="0 0 3"/>
        <parent link="link_01"/>
        <child link="link_02"/>
    </joint>

    <link name="link_02">
        <visual>
            <origin rpy="0 0 0" xyz="0 0 1.5"/>
            <geometry>
                <cylinder radius="0.3" length="3"/>
            </geometry>
        </visual>
    </link> 

    <joint name="link_02_link_03" type="revolute">
        <axis xyz="0 1 0"/>
        <limit effort="1000.0" lower="-3.14" upper="3.14" velocity="0.5"/>
        <origin rpy="0 0 0" xyz="0 0 3"/>
        <parent link="link_02"/>
        <child link="link_03"/>
    </joint>

    <link name="link_03">
        <visual>
            <origin rpy="0 0 0" xyz="0 0 0.5"/>
            <geometry>
                <box size="1 1 1"/>
            </geometry>
        </visual>
    </link> 

</robot>